<?xml version="1.0" ?>

<robot name="tug_turtlebot4">
  <!-- Create 3 base definition-->
  <link name="base_link">
    <visual>
      <origin rpy="0 0 1.5707963267948966" xyz="0 0 0.039200000000000006"/>
      <geometry>
        <mesh filename="package://irobot_create_description/meshes/body_visual.dae"/>
      </geometry>
    </visual>
    <collision name="create3_base_collision">
      <origin rpy="0 0 1.5707963267948966" xyz="0 0 0.04920000000000001"/>
      <geometry>
        <cylinder length="0.06" radius="0.16399999999999998"/>
      </geometry>
    </collision>
    <inertial>
      <origin xyz="0.022799999999999997 0 0.0742"/>
      <mass value="2.3"/>
      <inertia ixx="0.016155199999999998" ixy="0.0" ixz="0.0" iyy="0.016155199999999998" iyz="0.0" izz="0.03093039999999999"/>
    </inertial>
  </link>
  <gazebo reference="base_link">
    <visual>
      <material>
        <diffuse>0.011764705882352941 0.011764705882352941 0.011764705882352941 1</diffuse>
        <specular>0 0 0 1</specular>
        <emissive>0 0 0 1</emissive>
      </material>
    </visual>
  </gazebo>
  <joint name="bumper_joint" type="fixed">
    <parent link="base_link"/>
    <child link="bumper"/>
    <origin xyz="0 0 0.039200000000000006"/>
  </joint>
  <link name="bumper">
    <visual>
      <geometry>
        <mesh filename="package://irobot_create_description/meshes/bumper_visual.dae"/>
      </geometry>
    </visual>
    <collision>
      <geometry>
        <mesh filename="package://irobot_create_description/meshes/bumper_collision.dae"/>
      </geometry>
    </collision>
    <inertial>
      <origin xyz="0.08 0 0.02"/>
      <mass value="0.1"/>
      <inertia ixx="0.0013483753405" ixy="0.0000000454352" ixz="0.0000014434849" iyy="0.0002521736852" iyz="-0.0000000006721" izz="0.0015442525386"/>
    </inertial>
  </link>
  <gazebo reference="bumper">
    <mu1>0.1</mu1>
    <mu2>0.1</mu2>
    <maxVel>0.01</maxVel>
    <minDepth>0.001</minDepth>
    <maxContacts>10</maxContacts>
    <material>Gazebo/DarkGrey</material>
    <sensor name="bumper_contact_sensor" type="contact">
      <always_on>true</always_on>
      <update_rate>62.0</update_rate>
      <contact>
        <collision>bumper_collision</collision>
        <topic>tug_turtlebot4/bumper_contact</topic>
      </contact>
    </sensor>
  </gazebo>
  <gazebo reference="bumper_joint">
    <preserveFixedJoint>true</preserveFixedJoint>
  </gazebo>
  <joint name="bump_front_center_joint" type="fixed">
    <parent link="base_link"/>
    <child link="bump_front_center"/>
    <origin rpy="0 0 0" xyz="0.175 0 0.039"/>
  </joint>
  <link name="bump_front_center"/>
  <joint name="bump_front_left_joint" type="fixed">
    <parent link="base_link"/>
    <child link="bump_front_left"/>
    <origin rpy="0 0 0.5235985" xyz="0.02345 -0.0875 0.025"/>
  </joint>
  <link name="bump_front_left"/>
  <joint name="bump_front_right_joint" type="fixed">
    <parent link="base_link"/>
    <child link="bump_front_right"/>
    <origin rpy="0 0 -0.5235985" xyz="0.02345 0.0875 0.025"/>
  </joint>
  <link name="bump_front_right"/>
  <joint name="bump_left_joint" type="fixed">
    <parent link="base_link"/>
    <child link="bump_left"/>
    <origin rpy="0 0 1.047193" xyz="0.0875 -0.15155 0.025"/>
  </joint>
  <link name="bump_left"/>
  <joint name="bump_right_joint" type="fixed">
    <parent link="base_link"/>
    <child link="bump_right"/>
    <origin rpy="0 0 -1.047193" xyz="0.0875 0.15155 0.025"/>
  </joint>
  <link name="bump_right"/>
  <joint name="wheel_drop_left_joint" type="prismatic">
    <parent link="base_link"/>
    <child link="wheel_drop_left"/>
    <origin rpy="-1.5707963267948966 0 0" xyz="0 0.1165 0.04020000000000001"/>
    <axis xyz="0 1 0"/>
    <limit effort="0" lower="0" upper="0.03" velocity="0"/>
    <!-- Damping is big enough to not make the body oscillate too much when it's lifted up -->
    <dynamics damping="50" friction="0.1"/>
  </joint>
  <!-- Gazebo parameters to simulate a spring -->
  <gazebo reference="wheel_drop_left_joint">
    <provideFeedback>false</provideFeedback>
    <implicitSpringDamper>true</implicitSpringDamper>
    <!-- This value should be high enough so that the wheeldrop can
          retract with the robot's weight (mass * gravity) -->
    <springStiffness>450</springStiffness>
    <springReference>0.03</springReference>
  </gazebo>
  <link name="wheel_drop_left">
    <inertial>
      <mass value="0.05"/>
      <origin xyz="0 0 0"/>
      <inertia ixx="2.0833333333333336e-05" ixy="0.0" ixz="0.0" iyy="2.0833333333333336e-05" iyz="0.0" izz="2.0833333333333336e-05"/>
    </inertial>
  </link>
  <joint name="left_wheel_joint" type="continuous">
    <parent link="wheel_drop_left"/>
    <child link="left_wheel"/>
    <origin rpy="0 0 0" xyz="0 0 0"/>
    <axis xyz="0 0 1"/>
  </joint>
  <link name="left_wheel">
    <visual>
      <geometry>
        <cylinder length="0.015" radius="0.03575"/>
      </geometry>
      <!-- Give black color to wheels in Rviz -->
      <material name="black">
        <color rgba="0.1 0.1 0.1 1"/>
      </material>
    </visual>
    <collision>
      <geometry>
        <cylinder length="0.015" radius="0.03575"/>
      </geometry>
    </collision>
    <inertial>
      <origin xyz="0 0 0"/>
      <mass value="0.2"/>
      <inertia ixx="6.765312500000001e-05" ixy="0.0" ixz="0.0" iyy="6.765312500000001e-05" iyz="0.0" izz="0.00012780625000000003"/>
    </inertial>
  </link>
  <gazebo reference="left_wheel">
    <mu1>1.0</mu1>
    <mu2>1.0</mu2>
    <kp>1000000.0</kp>
    <kd>100.0</kd>
    <minDepth>0.0001</minDepth>
    <maxVel>1.0</maxVel>
    <material>Gazebo/DarkGrey</material>
  </gazebo>
  <joint name="wheel_drop_right_joint" type="prismatic">
    <parent link="base_link"/>
    <child link="wheel_drop_right"/>
    <origin rpy="-1.5707963267948966 0 0" xyz="0 -0.1165 0.04020000000000001"/>
    <axis xyz="0 1 0"/>
    <limit effort="0" lower="0" upper="0.03" velocity="0"/>
    <!-- Damping is big enough to not make the body oscillate too much when it's lifted up -->
    <dynamics damping="50" friction="0.1"/>
  </joint>
  <!-- Gazebo parameters to simulate a spring -->
  <gazebo reference="wheel_drop_right_joint">
    <provideFeedback>false</provideFeedback>
    <implicitSpringDamper>true</implicitSpringDamper>
    <!-- This value should be high enough so that the wheeldrop can
          retract with the robot's weight (mass * gravity) -->
    <springStiffness>450</springStiffness>
    <springReference>0.03</springReference>
  </gazebo>
  <link name="wheel_drop_right">
    <inertial>
      <mass value="0.05"/>
      <origin xyz="0 0 0"/>
      <inertia ixx="2.0833333333333336e-05" ixy="0.0" ixz="0.0" iyy="2.0833333333333336e-05" iyz="0.0" izz="2.0833333333333336e-05"/>
    </inertial>
  </link>
  <joint name="right_wheel_joint" type="continuous">
    <parent link="wheel_drop_right"/>
    <child link="right_wheel"/>
    <origin rpy="0 0 0" xyz="0 0 0"/>
    <axis xyz="0 0 1"/>
  </joint>
  <link name="right_wheel">
    <visual>
      <geometry>
        <cylinder length="0.015" radius="0.03575"/>
      </geometry>
      <!-- Give black color to wheels in Rviz -->
      <material name="black">
        <color rgba="0.1 0.1 0.1 1"/>
      </material>
    </visual>
    <collision>
      <geometry>
        <cylinder length="0.015" radius="0.03575"/>
      </geometry>
    </collision>
    <inertial>
      <origin xyz="0 0 0"/>
      <mass value="0.2"/>
      <inertia ixx="6.765312500000001e-05" ixy="0.0" ixz="0.0" iyy="6.765312500000001e-05" iyz="0.0" izz="0.00012780625000000003"/>
    </inertial>
  </link>
  <gazebo reference="right_wheel">
    <mu1>1.0</mu1>
    <mu2>1.0</mu2>
    <kp>1000000.0</kp>
    <kd>100.0</kd>
    <minDepth>0.0001</minDepth>
    <maxVel>1.0</maxVel>
    <material>Gazebo/DarkGrey</material>
  </gazebo>
  <joint name="front_caster_joint" type="fixed">
    <parent link="base_link"/>
    <child link="front_caster_link"/>
    <origin rpy="-1.5707963267948966 0 0" xyz="0.125 0 0.013900000000000003"/>
  </joint>
  <link name="front_caster_link">
    <visual>
      <geometry>
        <sphere radius="0.01"/>
      </geometry>
      <!-- Give black color to caster in Rviz -->
      <material name="black">
        <color rgba="0.1 0.1 0.1 1"/>
      </material>
    </visual>
    <collision>
      <geometry>
        <sphere radius="0.01"/>
      </geometry>
    </collision>
    <inertial>
      <mass value="0.01"/>
      <inertia ixx="4.0000000000000003e-07" ixy="0.0" ixz="0.0" iyy="4.0000000000000003e-07" iyz="0.0" izz="4.0000000000000003e-07"/>
    </inertial>
  </link>
  <gazebo reference="front_caster_joint">
    <preserveFixedJoint>true</preserveFixedJoint>
  </gazebo>
  <gazebo reference="front_caster_link">
    <material>Gazebo/DarkGrey</material>
    <mu1>0.01</mu1>
    <mu2>0.01</mu2>
    <kp>1000000.0</kp>
    <kd>1.0</kd>
  </gazebo>
  <joint name="imu_joint" type="fixed">
    <origin xyz="0.050613 0.043673 0.0844"/>
    <parent link="base_link"/>
    <child link="imu_link"/>
  </joint>
  <link name="imu_link">
    <inertial>
      <mass value="0.01"/>
      <origin xyz="0 0 0"/>
      <inertia ixx="1.6666666666666668e-07" ixy="0.0" ixz="0.0" iyy="1.6666666666666668e-07" iyz="0.0" izz="1.6666666666666668e-07"/>
    </inertial>
  </link>
  <gazebo reference="imu_link">
    <sensor name="imu" type="imu">
      <always_on>true</always_on>
      <update_rate>62</update_rate>
      <imu>
        <angular_velocity>
          <x>
            <noise type="gaussian">
              <mean>0.0</mean>
              <stddev>0.0</stddev>
            </noise>
          </x>
          <y>
            <noise type="gaussian">
              <mean>0.0</mean>
              <stddev>0.0</stddev>
            </noise>
          </y>
          <z>
            <noise type="gaussian">
              <mean>0.0</mean>
              <stddev>0.0</stddev>
            </noise>
          </z>
        </angular_velocity>
        <linear_acceleration>
          <x>
            <noise type="gaussian">
              <mean>0.0</mean>
              <stddev>0.0</stddev>
            </noise>
          </x>
          <y>
            <noise type="gaussian">
              <mean>0.0</mean>
              <stddev>0.0</stddev>
            </noise>
          </y>
          <z>
            <noise type="gaussian">
              <mean>0.0</mean>
              <stddev>0.0</stddev>
            </noise>
          </z>
        </linear_acceleration>
      </imu>
    </sensor>
  </gazebo>
  <gazebo reference="imu_joint">
    <preserveFixedJoint>true</preserveFixedJoint>
  </gazebo>
  <joint name="mouse_joint" type="fixed">
    <origin rpy="0 0 -0.7853981633974483" xyz="0.1015 0.087 0.009200000000000007"/>
    <parent link="base_link"/>
    <child link="mouse"/>
  </joint>
  <link name="mouse">
    <inertial>
      <mass value="0.01"/>
      <origin xyz="0 0 0"/>
      <inertia ixx="1.6666666666666668e-07" ixy="0.0" ixz="0.0" iyy="1.6666666666666668e-07" iyz="0.0" izz="1.6666666666666668e-07"/>
    </inertial>
  </link>
  <gazebo reference="mouse_joint">
    <preserveFixedJoint>true</preserveFixedJoint>
  </gazebo>
  <joint name="cliff_side_left_joint" type="fixed">
    <origin rpy="0 1.3962634015954636 2.921681167838508" xyz="0.06 0.145 0.01920000000000001"/>
    <parent link="base_link"/>
    <child link="cliff_side_left"/>
  </joint>
  <link name="cliff_side_left">
    <inertial>
      <mass value="0.01"/>
      <origin xyz="0 0 0"/>
      <inertia ixx="1.6666666666666668e-07" ixy="0.0" ixz="0.0" iyy="1.6666666666666668e-07" iyz="0.0" izz="1.6666666666666668e-07"/>
    </inertial>
  </link>
  <gazebo reference="cliff_side_left">
    <sensor name="cliff_side_left" type="gpu_lidar">
      <update_rate>62</update_rate>
      <visualize>False</visualize>
      <always_on>true</always_on>
      <lidar>
        <scan>
          <horizontal>
            <samples>1.0</samples>
            <resolution>1.0</resolution>
            <min_angle>-0.04363323129985824</min_angle>
            <max_angle>0.04363323129985824</max_angle>
          </horizontal>
          <vertical>
            <samples>1</samples>
            <resolution>1</resolution>
            <min_angle>0</min_angle>
            <max_angle>0</max_angle>
          </vertical>
        </scan>
        <range>
          <min>0.0001</min>
          <max>0.15</max>
          <resolution>1.0</resolution>
        </range>
      </lidar>
    </sensor>
  </gazebo>
  <joint name="cliff_side_right_joint" type="fixed">
    <origin rpy="0 1.3962634015954636 -2.921681167838508" xyz="0.06 -0.145 0.01920000000000001"/>
    <parent link="base_link"/>
    <child link="cliff_side_right"/>
  </joint>
  <link name="cliff_side_right">
    <inertial>
      <mass value="0.01"/>
      <origin xyz="0 0 0"/>
      <inertia ixx="1.6666666666666668e-07" ixy="0.0" ixz="0.0" iyy="1.6666666666666668e-07" iyz="0.0" izz="1.6666666666666668e-07"/>
    </inertial>
  </link>
  <gazebo reference="cliff_side_right">
    <sensor name="cliff_side_right" type="gpu_lidar">
      <update_rate>62</update_rate>
      <visualize>False</visualize>
      <always_on>true</always_on>
      <lidar>
        <scan>
          <horizontal>
            <samples>1.0</samples>
            <resolution>1.0</resolution>
            <min_angle>-0.04363323129985824</min_angle>
            <max_angle>0.04363323129985824</max_angle>
          </horizontal>
          <vertical>
            <samples>1</samples>
            <resolution>1</resolution>
            <min_angle>0</min_angle>
            <max_angle>0</max_angle>
          </vertical>
        </scan>
        <range>
          <min>0.0001</min>
          <max>0.15</max>
          <resolution>1.0</resolution>
        </range>
      </lidar>
    </sensor>
  </gazebo>
  <joint name="cliff_front_left_joint" type="fixed">
    <origin rpy="0 1.3962634015954636 1.1397000015522971" xyz="0.16 0.045 0.01920000000000001"/>
    <parent link="base_link"/>
    <child link="cliff_front_left"/>
  </joint>
  <link name="cliff_front_left">
    <inertial>
      <mass value="0.01"/>
      <origin xyz="0 0 0"/>
      <inertia ixx="1.6666666666666668e-07" ixy="0.0" ixz="0.0" iyy="1.6666666666666668e-07" iyz="0.0" izz="1.6666666666666668e-07"/>
    </inertial>
  </link>
  <gazebo reference="cliff_front_left">
    <sensor name="cliff_front_left" type="gpu_lidar">
      <update_rate>62</update_rate>
      <visualize>False</visualize>
      <always_on>true</always_on>
      <lidar>
        <scan>
          <horizontal>
            <samples>1.0</samples>
            <resolution>1.0</resolution>
            <min_angle>-0.04363323129985824</min_angle>
            <max_angle>0.04363323129985824</max_angle>
          </horizontal>
          <vertical>
            <samples>1</samples>
            <resolution>1</resolution>
            <min_angle>0</min_angle>
            <max_angle>0</max_angle>
          </vertical>
        </scan>
        <range>
          <min>0.0001</min>
          <max>0.15</max>
          <resolution>1.0</resolution>
        </range>
      </lidar>
    </sensor>
  </gazebo>
  <joint name="cliff_front_right_joint" type="fixed">
    <origin rpy="0 1.3962634015954636 -1.1397000015522971" xyz="0.16 -0.045 0.01920000000000001"/>
    <parent link="base_link"/>
    <child link="cliff_front_right"/>
  </joint>
  <link name="cliff_front_right">
    <inertial>
      <mass value="0.01"/>
      <origin xyz="0 0 0"/>
      <inertia ixx="1.6666666666666668e-07" ixy="0.0" ixz="0.0" iyy="1.6666666666666668e-07" iyz="0.0" izz="1.6666666666666668e-07"/>
    </inertial>
  </link>
  <gazebo reference="cliff_front_right">
    <sensor name="cliff_front_right" type="gpu_lidar">
      <update_rate>62</update_rate>
      <visualize>False</visualize>
      <always_on>true</always_on>
      <lidar>
        <scan>
          <horizontal>
            <samples>1.0</samples>
            <resolution>1.0</resolution>
            <min_angle>-0.04363323129985824</min_angle>
            <max_angle>0.04363323129985824</max_angle>
          </horizontal>
          <vertical>
            <samples>1</samples>
            <resolution>1</resolution>
            <min_angle>0</min_angle>
            <max_angle>0</max_angle>
          </vertical>
        </scan>
        <range>
          <min>0.0001</min>
          <max>0.15</max>
          <resolution>1.0</resolution>
        </range>
      </lidar>
    </sensor>
  </gazebo>
  <joint name="ir_intensity_front_center_left_joint" type="fixed">
    <origin xyz="0.1540 0 0.05720000000000001"/>
    <parent link="base_link"/>
    <child link="ir_intensity_front_center_left"/>
  </joint>
  <link name="ir_intensity_front_center_left">
    <inertial>
      <mass value="0.01"/>
      <origin xyz="0 0 0"/>
      <inertia ixx="1.6666666666666668e-07" ixy="0.0" ixz="0.0" iyy="1.6666666666666668e-07" iyz="0.0" izz="1.6666666666666668e-07"/>
    </inertial>
  </link>
  <gazebo reference="ir_intensity_front_center_left_joint">
    <preserveFixedJoint>true</preserveFixedJoint>
  </gazebo>
  <gazebo reference="ir_intensity_front_center_left">
    <sensor name="ir_intensity_front_center_left" type="gpu_lidar">
      <update_rate>62.0</update_rate>
      <visualize>False</visualize>
      <always_on>true</always_on>
      <lidar>
        <scan>
          <horizontal>
            <samples>5</samples>
            <resolution>1.0</resolution>
            <min_angle>-0.08726646259971647</min_angle>
            <max_angle>0.08726646259971647</max_angle>
          </horizontal>
          <vertical>
            <samples>5</samples>
            <resolution>1.0</resolution>
            <min_angle>-0.08726646259971647</min_angle>
            <max_angle>0.08726646259971647</max_angle>
          </vertical>
        </scan>
        <range>
          <min>0.025</min>
          <max>0.2</max>
          <resolution>1.0</resolution>
        </range>
      </lidar>
    </sensor>
  </gazebo>
  <joint name="ir_intensity_front_center_right_joint" type="fixed">
    <origin rpy="0 0 -0.436" xyz="0.1396 -0.0651 0.05720000000000001"/>
    <parent link="base_link"/>
    <child link="ir_intensity_front_center_right"/>
  </joint>
  <link name="ir_intensity_front_center_right">
    <inertial>
      <mass value="0.01"/>
      <origin xyz="0 0 0"/>
      <inertia ixx="1.6666666666666668e-07" ixy="0.0" ixz="0.0" iyy="1.6666666666666668e-07" iyz="0.0" izz="1.6666666666666668e-07"/>
    </inertial>
  </link>
  <gazebo reference="ir_intensity_front_center_right_joint">
    <preserveFixedJoint>true</preserveFixedJoint>
  </gazebo>
  <gazebo reference="ir_intensity_front_center_right">
    <sensor name="ir_intensity_front_center_right" type="gpu_lidar">
      <update_rate>62.0</update_rate>
      <visualize>False</visualize>
      <always_on>true</always_on>
      <lidar>
        <scan>
          <horizontal>
            <samples>5</samples>
            <resolution>1.0</resolution>
            <min_angle>-0.08726646259971647</min_angle>
            <max_angle>0.08726646259971647</max_angle>
          </horizontal>
          <vertical>
            <samples>5</samples>
            <resolution>1.0</resolution>
            <min_angle>-0.08726646259971647</min_angle>
            <max_angle>0.08726646259971647</max_angle>
          </vertical>
        </scan>
        <range>
          <min>0.025</min>
          <max>0.2</max>
          <resolution>1.0</resolution>
        </range>
      </lidar>
    </sensor>
  </gazebo>
  <joint name="ir_intensity_front_left_joint" type="fixed">
    <origin rpy="0 0 0.436" xyz="0.1396 0.0651 0.05720000000000001"/>
    <parent link="base_link"/>
    <child link="ir_intensity_front_left"/>
  </joint>
  <link name="ir_intensity_front_left">
    <inertial>
      <mass value="0.01"/>
      <origin xyz="0 0 0"/>
      <inertia ixx="1.6666666666666668e-07" ixy="0.0" ixz="0.0" iyy="1.6666666666666668e-07" iyz="0.0" izz="1.6666666666666668e-07"/>
    </inertial>
  </link>
  <gazebo reference="ir_intensity_front_left_joint">
    <preserveFixedJoint>true</preserveFixedJoint>
  </gazebo>
  <gazebo reference="ir_intensity_front_left">
    <sensor name="ir_intensity_front_left" type="gpu_lidar">
      <update_rate>62.0</update_rate>
      <visualize>False</visualize>
      <always_on>true</always_on>
      <lidar>
        <scan>
          <horizontal>
            <samples>5</samples>
            <resolution>1.0</resolution>
            <min_angle>-0.08726646259971647</min_angle>
            <max_angle>0.08726646259971647</max_angle>
          </horizontal>
          <vertical>
            <samples>5</samples>
            <resolution>1.0</resolution>
            <min_angle>-0.08726646259971647</min_angle>
            <max_angle>0.08726646259971647</max_angle>
          </vertical>
        </scan>
        <range>
          <min>0.025</min>
          <max>0.2</max>
          <resolution>1.0</resolution>
        </range>
      </lidar>
    </sensor>
  </gazebo>
  <joint name="ir_intensity_front_right_joint" type="fixed">
    <origin rpy="0 0 -0.873" xyz="0.0990 -0.1180 0.05720000000000001"/>
    <parent link="base_link"/>
    <child link="ir_intensity_front_right"/>
  </joint>
  <link name="ir_intensity_front_right">
    <inertial>
      <mass value="0.01"/>
      <origin xyz="0 0 0"/>
      <inertia ixx="1.6666666666666668e-07" ixy="0.0" ixz="0.0" iyy="1.6666666666666668e-07" iyz="0.0" izz="1.6666666666666668e-07"/>
    </inertial>
  </link>
  <gazebo reference="ir_intensity_front_right_joint">
    <preserveFixedJoint>true</preserveFixedJoint>
  </gazebo>
  <gazebo reference="ir_intensity_front_right">
    <sensor name="ir_intensity_front_right" type="gpu_lidar">
      <update_rate>62.0</update_rate>
      <visualize>False</visualize>
      <always_on>true</always_on>
      <lidar>
        <scan>
          <horizontal>
            <samples>5</samples>
            <resolution>1.0</resolution>
            <min_angle>-0.08726646259971647</min_angle>
            <max_angle>0.08726646259971647</max_angle>
          </horizontal>
          <vertical>
            <samples>5</samples>
            <resolution>1.0</resolution>
            <min_angle>-0.08726646259971647</min_angle>
            <max_angle>0.08726646259971647</max_angle>
          </vertical>
        </scan>
        <range>
          <min>0.025</min>
          <max>0.2</max>
          <resolution>1.0</resolution>
        </range>
      </lidar>
    </sensor>
  </gazebo>
  <joint name="ir_intensity_left_joint" type="fixed">
    <origin rpy="0 0 0.873" xyz="0.0990 0.1180 0.05720000000000001"/>
    <parent link="base_link"/>
    <child link="ir_intensity_left"/>
  </joint>
  <link name="ir_intensity_left">
    <inertial>
      <mass value="0.01"/>
      <origin xyz="0 0 0"/>
      <inertia ixx="1.6666666666666668e-07" ixy="0.0" ixz="0.0" iyy="1.6666666666666668e-07" iyz="0.0" izz="1.6666666666666668e-07"/>
    </inertial>
  </link>
  <gazebo reference="ir_intensity_left_joint">
    <preserveFixedJoint>true</preserveFixedJoint>
  </gazebo>
  <gazebo reference="ir_intensity_left">
    <sensor name="ir_intensity_left" type="gpu_lidar">
      <update_rate>62.0</update_rate>
      <visualize>False</visualize>
      <always_on>true</always_on>
      <lidar>
        <scan>
          <horizontal>
            <samples>5</samples>
            <resolution>1.0</resolution>
            <min_angle>-0.08726646259971647</min_angle>
            <max_angle>0.08726646259971647</max_angle>
          </horizontal>
          <vertical>
            <samples>5</samples>
            <resolution>1.0</resolution>
            <min_angle>-0.08726646259971647</min_angle>
            <max_angle>0.08726646259971647</max_angle>
          </vertical>
        </scan>
        <range>
          <min>0.025</min>
          <max>0.2</max>
          <resolution>1.0</resolution>
        </range>
      </lidar>
    </sensor>
  </gazebo>
  <joint name="ir_intensity_right_joint" type="fixed">
    <origin rpy="0 0 -1.309" xyz="0.0399 -0.1488 0.05720000000000001"/>
    <parent link="base_link"/>
    <child link="ir_intensity_right"/>
  </joint>
  <link name="ir_intensity_right">
    <inertial>
      <mass value="0.01"/>
      <origin xyz="0 0 0"/>
      <inertia ixx="1.6666666666666668e-07" ixy="0.0" ixz="0.0" iyy="1.6666666666666668e-07" iyz="0.0" izz="1.6666666666666668e-07"/>
    </inertial>
  </link>
  <gazebo reference="ir_intensity_right_joint">
    <preserveFixedJoint>true</preserveFixedJoint>
  </gazebo>
  <gazebo reference="ir_intensity_right">
    <sensor name="ir_intensity_right" type="gpu_lidar">
      <update_rate>62.0</update_rate>
      <visualize>False</visualize>
      <always_on>true</always_on>
      <lidar>
        <scan>
          <horizontal>
            <samples>5</samples>
            <resolution>1.0</resolution>
            <min_angle>-0.08726646259971647</min_angle>
            <max_angle>0.08726646259971647</max_angle>
          </horizontal>
          <vertical>
            <samples>5</samples>
            <resolution>1.0</resolution>
            <min_angle>-0.08726646259971647</min_angle>
            <max_angle>0.08726646259971647</max_angle>
          </vertical>
        </scan>
        <range>
          <min>0.025</min>
          <max>0.2</max>
          <resolution>1.0</resolution>
        </range>
      </lidar>
    </sensor>
  </gazebo>
  <joint name="ir_intensity_side_left_joint" type="fixed">
    <origin rpy="0 0 1.309" xyz="0.0399 0.1488 0.05720000000000001"/>
    <parent link="base_link"/>
    <child link="ir_intensity_side_left"/>
  </joint>
  <link name="ir_intensity_side_left">
    <inertial>
      <mass value="0.01"/>
      <origin xyz="0 0 0"/>
      <inertia ixx="1.6666666666666668e-07" ixy="0.0" ixz="0.0" iyy="1.6666666666666668e-07" iyz="0.0" izz="1.6666666666666668e-07"/>
    </inertial>
  </link>
  <gazebo reference="ir_intensity_side_left_joint">
    <preserveFixedJoint>true</preserveFixedJoint>
  </gazebo>
  <gazebo reference="ir_intensity_side_left">
    <sensor name="ir_intensity_side_left" type="gpu_lidar">
      <update_rate>62.0</update_rate>
      <visualize>False</visualize>
      <always_on>true</always_on>
      <lidar>
        <scan>
          <horizontal>
            <samples>5</samples>
            <resolution>1.0</resolution>
            <min_angle>-0.08726646259971647</min_angle>
            <max_angle>0.08726646259971647</max_angle>
          </horizontal>
          <vertical>
            <samples>5</samples>
            <resolution>1.0</resolution>
            <min_angle>-0.08726646259971647</min_angle>
            <max_angle>0.08726646259971647</max_angle>
          </vertical>
        </scan>
        <range>
          <min>0.025</min>
          <max>0.2</max>
          <resolution>1.0</resolution>
        </range>
      </lidar>
    </sensor>
  </gazebo>
  <joint name="button_1_joint" type="fixed">
    <parent link="base_link"/>
    <child link="button_1"/>
    <origin rpy="0 -1.5707963267948966 0" xyz="0.06 0.37 0.1442"/>
  </joint>
  <link name="button_1"/>
  <joint name="button_2_joint" type="fixed">
    <parent link="base_link"/>
    <child link="button_2"/>
    <origin rpy="0 -1.5707963267948966 0" xyz="0.06 -0.37 0.1442"/>
  </joint>
  <link name="button_2"/>
  <joint name="button_power_joint" type="fixed">
    <parent link="base_link"/>
    <child link="button_power"/>
    <origin rpy="0 -1.5707963267948966 0" xyz="0.06 0 0.1442"/>
  </joint>
  <link name="button_power"/>
  <joint name="ir_omni_joint" type="fixed">
    <origin xyz="0.153 0 0.09920000000000001"/>
    <parent link="base_link"/>
    <child link="ir_omni"/>
  </joint>
  <link name="ir_omni">
    <inertial>
      <mass value="0.01"/>
      <origin xyz="0 0 0"/>
      <inertia ixx="1.6666666666666668e-07" ixy="0.0" ixz="0.0" iyy="1.6666666666666668e-07" iyz="0.0" izz="1.6666666666666668e-07"/>
    </inertial>
  </link>
  <gazebo reference="ir_omni_joint">
    <preserveFixedJoint>true</preserveFixedJoint>
  </gazebo>

  <!-- Plugins -->
  <gazebo>
    <plugin filename="libignition-gazebo-contact-system.so" name="ignition::gazebo::systems::Contact" />
    <plugin filename="libignition-gazebo-sensors-system.so" name="ignition::gazebo::systems::Sensors">
      <render_engine>ogre</render_engine>
    </plugin>

    <plugin filename="libignition-gazebo-pose-publisher-system.so" name="ignition::gazebo::systems::PosePublisher">
      <publish_link_pose>false</publish_link_pose>
      <publish_nested_model_pose>true</publish_nested_model_pose>
      <update_frequency>50</update_frequency>
      <use_pose_vector_msg>true</use_pose_vector_msg>
    </plugin>

    <plugin filename="libignition-gazebo-joint-state-publisher-system.so" name="ignition::gazebo::systems::JointStatePublisher">
      <topic>/model/tug_turtlebot4/joint_states</topic>
    </plugin>

    <plugin filename="libignition-gazebo6-diff-drive-system.so" name="ignition::gazebo::systems::DiffDrive">
      <!-- Wheel information -->
      <left_joint>left_wheel_joint</left_joint>
      <right_joint>right_wheel_joint</right_joint>
      <wheel_separation>0.233</wheel_separation>
      <wheel_radius>0.03575</wheel_radius>

      <!-- Limits -->
      <min_linear_velocity>-0.46</min_linear_velocity>
      <max_linear_velocity>0.46</max_linear_velocity>
      <min_linear_accerleration>-0.9</min_linear_accerleration>
      <max_linear_acceleration>0.9</max_linear_acceleration>

      <min_angualr_velocity>-1.9</min_angualr_velocity>
      <max_angular_velocity>1.9</max_angular_velocity>
      <min_angular_acceleration>-7.725</min_angular_acceleration>
      <max_angular_acceleration>7.725</max_angular_acceleration>
    </plugin>
  </gazebo>

  <!-- Turtlebot4 sensor definitions -->
  <joint name="rplidar_joint" type="fixed">
    <parent link="base_link"/>
    <child link="rplidar_link"/>
    <origin rpy="0 0 1.5707963267948966" xyz="0.00393584 0.0 0.13949272000000001"/>
  </joint>
  <link name="rplidar_link">
    <visual>
      <geometry>
        <mesh filename="package://turtlebot4_description/meshes/rplidar.dae" scale="1 1 1"/>
      </geometry>
    </visual>
    <collision>
      <origin xyz="0.0 0.013000000000000001 -0.019"/>
      <geometry>
        <box size="0.071 0.1 0.06"/>
      </geometry>
    </collision>
    <inertial>
      <mass value="0.17"/>
      <origin xyz="0 0 0"/>
      <inertia ixx="0.0001926666666666667" ixy="0.0" ixz="0.0" iyy="0.00012241416666666666" iyz="0.0" izz="0.00021308083333333337"/>
    </inertial>
  </link>
  <gazebo reference="rplidar_link">
    <sensor name="rplidar" type="gpu_lidar">
      <topic>/model/tug_turtlebot4/scan</topic>
      <gz_frame_id>rplidar_link</gz_frame_id>
      <update_rate>50</update_rate>
      <visualize>1</visualize>
      <always_on>true</always_on>
      <lidar>
        <scan>
          <horizontal>
            <samples>640</samples>
            <resolution>1.0</resolution>
            <min_angle>-3.141592653589793</min_angle>
            <max_angle>3.141592653589793</max_angle>
          </horizontal>
          <vertical>
            <samples>1</samples>
            <resolution>1</resolution>
            <min_angle>0</min_angle>
            <max_angle>0</max_angle>
          </vertical>
        </scan>
        <range>
          <min>0.164</min>
          <max>12.0</max>
          <resolution>0.01</resolution>
        </range>
      </lidar>
    </sensor>
    <visual>
      <material>
        <diffuse>0.011764705882352941 0.011764705882352941 0.011764705882352941 1</diffuse>
        <specular>0 0 0 1</specular>
        <emissive>0 0 0 1</emissive>
      </material>
    </visual>
  </gazebo>
  <gazebo reference="rplidar_joint">
    <preserveFixedJoint>true</preserveFixedJoint>
  </gazebo>
  <joint name="oakd_camera_bracket_joint" type="fixed">
    <parent link="base_link"/>
    <child link="oakd_camera_bracket"/>
    <origin xyz="-0.09 0.0 0.09334772000000001"/>
  </joint>
  <link name="oakd_camera_bracket">
    <visual>
      <geometry>
        <mesh filename="package://turtlebot4_description/meshes/camera_bracket.dae" scale="1 1 1"/>
      </geometry>
    </visual>
    <inertial>
      <mass value="0.033"/>
      <inertia ixx="0.0000579181" ixy="0.0" ixz="0.0000090679" iyy="0.0000559785" iyz="0.0" izz="0.0000140955"/>
    </inertial>
  </link>
  <gazebo reference="oakd_camera_bracket_joint">
    <preserveFixedJoint>true</preserveFixedJoint>
  </gazebo>
  <gazebo reference="oakd_camera_bracket">
    <visual>
      <material>
        <diffuse>0 0 0 1</diffuse>
        <specular>0.3137254901960784 0.3137254901960784 0.3137254901960784 1</specular>
        <emissive>0 0 0 1</emissive>
      </material>
    </visual>
  </gazebo>
  <!-- Base frame -->
  <joint name="oakd_joint" type="fixed">
    <parent link="oakd_camera_bracket"/>
    <child link="oakd_link"/>
    <origin xyz="0.052940259999999996 0.0 0.0925385"/>
  </joint>
  <link name="oakd_link">
    <visual>
      <geometry>
        <mesh filename="package://turtlebot4_description/meshes/oakd_lite.dae" scale="1 1 1"/>
      </geometry>
    </visual>
    <collision>
      <origin xyz="-0.011000000000000001 0.0 -0.005"/>
      <geometry>
        <box size="0.0225 0.09699999999999999 0.03"/>
      </geometry>
    </collision>
    <inertial>
      <mass value="0.061"/>
      <inertia ixx="0.00000202475" ixy="0.0" ixz="0.0" iyy="0.00001527320" iyz="0.0" izz="0.00001605536"/>
    </inertial>
  </link>
  <!-- RGB Camera -->
  <link name="oakd_rgb_camera_frame">
    <inertial>
      <mass value="0.01"/>
      <origin xyz="0 0 0"/>
      <inertia ixx="1.6666666666666668e-07" ixy="0.0" ixz="0.0" iyy="1.6666666666666668e-07" iyz="0.0" izz="1.6666666666666668e-07"/>
    </inertial>
  </link>
  <joint name="oakd_rgb_camera_joint" type="fixed">
    <parent link="oakd_link"/>
    <child link="oakd_rgb_camera_frame"/>
    <origin rpy="0 0 0" xyz="0 0 0"/>
  </joint>
  <link name="oakd_rgb_camera_optical_frame">
    <inertial>
      <mass value="0.01"/>
      <origin xyz="0 0 0"/>
      <inertia ixx="1.6666666666666668e-07" ixy="0.0" ixz="0.0" iyy="1.6666666666666668e-07" iyz="0.0" izz="1.6666666666666668e-07"/>
    </inertial>
  </link>
  <joint name="oakd_rgb_camera_optical_joint" type="fixed">
    <origin rpy="-1.5707963267948966 0.0 -1.5707963267948966" xyz="0 0 0"/>
    <parent link="oakd_rgb_camera_frame"/>
    <child link="oakd_rgb_camera_optical_frame"/>
  </joint>
  <!-- Left Camera -->
  <link name="oakd_left_camera_frame">
    <inertial>
      <mass value="0.01"/>
      <origin xyz="0 0 0"/>
      <inertia ixx="1.6666666666666668e-07" ixy="0.0" ixz="0.0" iyy="1.6666666666666668e-07" iyz="0.0" izz="1.6666666666666668e-07"/>
    </inertial>
  </link>
  <joint name="oakd_left_camera_joint" type="fixed">
    <parent link="oakd_link"/>
    <child link="oakd_left_camera_frame"/>
    <origin rpy="0 0 0" xyz="0 0.0375 0"/>
  </joint>
  <link name="oakd_left_camera_optical_frame">
    <inertial>
      <mass value="0.01"/>
      <origin xyz="0 0 0"/>
      <inertia ixx="1.6666666666666668e-07" ixy="0.0" ixz="0.0" iyy="1.6666666666666668e-07" iyz="0.0" izz="1.6666666666666668e-07"/>
    </inertial>
  </link>
  <joint name="oakd_left_camera_optical_joint" type="fixed">
    <origin rpy="-1.5707963267948966 0.0 -1.5707963267948966" xyz="0 0 0"/>
    <parent link="oakd_left_camera_frame"/>
    <child link="oakd_left_camera_optical_frame"/>
  </joint>
  <!-- Right Camera -->
  <link name="oakd_right_camera_frame">
    <inertial>
      <mass value="0.01"/>
      <origin xyz="0 0 0"/>
      <inertia ixx="1.6666666666666668e-07" ixy="0.0" ixz="0.0" iyy="1.6666666666666668e-07" iyz="0.0" izz="1.6666666666666668e-07"/>
    </inertial>
  </link>
  <joint name="oakd_right_camera_joint" type="fixed">
    <parent link="oakd_link"/>
    <child link="oakd_right_camera_frame"/>
    <origin rpy="0 0 0" xyz="0 -0.0375 0"/>
  </joint>
  <link name="oakd_right_camera_optical_frame">
    <inertial>
      <mass value="0.01"/>
      <origin xyz="0 0 0"/>
      <inertia ixx="1.6666666666666668e-07" ixy="0.0" ixz="0.0" iyy="1.6666666666666668e-07" iyz="0.0" izz="1.6666666666666668e-07"/>
    </inertial>
  </link>
  <joint name="oakd_right_camera_optical_joint" type="fixed">
    <origin rpy="-1.5707963267948966 0.0 -1.5707963267948966" xyz="0 0 0"/>
    <parent link="oakd_right_camera_frame"/>
    <child link="oakd_right_camera_optical_frame"/>
  </joint>
  <!-- IMU -->
  <link name="oakd_imu_frame">
    <inertial>
      <mass value="0.01"/>
      <origin xyz="0 0 0"/>
      <inertia ixx="1.6666666666666668e-07" ixy="0.0" ixz="0.0" iyy="1.6666666666666668e-07" iyz="0.0" izz="1.6666666666666668e-07"/>
    </inertial>
  </link>
  <joint name="oakd_imu_joint" type="fixed">
    <parent link="oakd_link"/>
    <child link="oakd_imu_frame"/>
    <origin rpy="-1.5707963267948966 0 -1.5707963267948966" xyz="0 0 0"/>
  </joint>
  <!-- Gazebo links and joints -->
  <gazebo reference="oakd_rgb_camera_frame">
    <sensor name="rgbd_camera" type="rgbd_camera">
      <camera>
        <horizontal_fov>1.25</horizontal_fov>
        <image>
          <width>320</width>
          <height>240</height>
        </image>
        <clip>
          <near>0.3</near>
          <far>100</far>
        </clip>
        <optical_frame_id>oakd_rgb_camera_optical_frame</optical_frame_id>
      </camera>
      <always_on>1</always_on>
      <update_rate>30</update_rate>
      <visualize>true</visualize>
    </sensor>
    <visual>
      <material>
        <diffuse>0.011764705882352941 0.011764705882352941 0.011764705882352941 1</diffuse>
        <specular>0 0 0 1</specular>
        <emissive>0 0 0 1</emissive>
      </material>
    </visual>
  </gazebo>
  <gazebo reference="oakd_joint">
    <preserveFixedJoint>true</preserveFixedJoint>
  </gazebo>
  <gazebo reference="oakd_rgb_camera_joint">
    <preserveFixedJoint>true</preserveFixedJoint>
  </gazebo>
  <gazebo reference="oakd_rgb_camera_optical_joint">
    <preserveFixedJoint>true</preserveFixedJoint>
  </gazebo>
  <gazebo reference="oakd_left_camera_joint">
    <preserveFixedJoint>true</preserveFixedJoint>
  </gazebo>
  <gazebo reference="oakd_left_camera_optical_joint">
    <preserveFixedJoint>true</preserveFixedJoint>
  </gazebo>
  <gazebo reference="oakd_right_camera_joint">
    <preserveFixedJoint>true</preserveFixedJoint>
  </gazebo>
  <gazebo reference="oakd_right_camera_optical_joint">
    <preserveFixedJoint>true</preserveFixedJoint>
  </gazebo>
  <gazebo reference="oakd_imu_joint">
    <preserveFixedJoint>true</preserveFixedJoint>
  </gazebo>
</robot>
